2022-07-27 08:51:51,742 INFO    StreamThr :2331651 [internal.py:wandb_internal():90] W&B internal server running at pid: 2331651, started at: 2022-07-27 08:51:51.741965
2022-07-27 08:51:51,746 DEBUG   HandlerThread:2331651 [handler.py:handle_request():140] handle_request: status
2022-07-27 08:51:51,749 DEBUG   SenderThread:2331651 [sender.py:send_request():250] send_request: status
2022-07-27 08:51:51,752 DEBUG   SenderThread:2331651 [sender.py:send():236] send: header
2022-07-27 08:51:51,752 INFO    WriterThread:2331651 [datastore.py:open_for_write():75] open: ./wandb/run-20220727_085151-2o4khaul/run-2o4khaul.wandb
2022-07-27 08:51:51,892 DEBUG   SenderThread:2331651 [sender.py:send():236] send: run
2022-07-27 08:51:51,896 INFO    SenderThread:2331651 [sender.py:_maybe_setup_resume():493] checking resume status for None/ubc/2o4khaul
2022-07-27 08:52:09,410 ERROR   SenderThread:2331651 [internal_api.py:execute():161] 409 response executing GraphQL.
2022-07-27 08:52:09,411 ERROR   SenderThread:2331651 [internal_api.py:execute():162] {"errors":[{"message":"Error 1062: Duplicate entry '33053408-2o4khaul' for key 'PRIMARY'","path":["upsertBucket"]}],"data":{"upsertBucket":null}}
2022-07-27 08:52:09,896 INFO    WriterThread:2331651 [datastore.py:close():279] close: ./wandb/run-20220727_085151-2o4khaul/run-2o4khaul.wandb
2022-07-27 08:52:09,914 INFO    HandlerThread:2331651 [handler.py:finish():806] shutting down handler
2022-07-27 08:52:09,914 ERROR   StreamThr :2331651 [internal.py:wandb_internal():165] Thread SenderThread:
Traceback (most recent call last):
  File "/usr/local/lib/python3.8/dist-packages/wandb/apis/normalize.py", line 25, in wrapper
    return func(*args, **kwargs)
  File "/usr/local/lib/python3.8/dist-packages/wandb/sdk/internal/internal_api.py", line 1341, in upsert_run
    response = self.gql(mutation, variable_values=variable_values, **kwargs)
  File "/usr/local/lib/python3.8/dist-packages/wandb/sdk/lib/retry.py", line 108, in __call__
    result = self._call_fn(*args, **kwargs)
  File "/usr/local/lib/python3.8/dist-packages/wandb/sdk/internal/internal_api.py", line 158, in execute
    return self.client.execute(*args, **kwargs)
  File "/usr/local/lib/python3.8/dist-packages/wandb/vendor/gql-0.2.0/wandb_gql/client.py", line 52, in execute
    result = self._get_result(document, *args, **kwargs)
  File "/usr/local/lib/python3.8/dist-packages/wandb/vendor/gql-0.2.0/wandb_gql/client.py", line 60, in _get_result
    return self.transport.execute(document, *args, **kwargs)
  File "/usr/local/lib/python3.8/dist-packages/wandb/vendor/gql-0.2.0/wandb_gql/transport/requests.py", line 39, in execute
    request.raise_for_status()
  File "/usr/local/lib/python3.8/dist-packages/requests/models.py", line 1022, in raise_for_status
    raise HTTPError(http_error_msg, response=self)
requests.exceptions.HTTPError: 409 Client Error: Conflict for url: https://api.wandb.ai/graphql

During handling of the above exception, another exception occurred:

Traceback (most recent call last):
  File "/usr/local/lib/python3.8/dist-packages/wandb/sdk/internal/internal_util.py", line 51, in run
    self._run()
  File "/usr/local/lib/python3.8/dist-packages/wandb/sdk/internal/internal_util.py", line 102, in _run
    self._process(record)
  File "/usr/local/lib/python3.8/dist-packages/wandb/sdk/internal/internal.py", line 310, in _process
    self._sm.send(record)
  File "/usr/local/lib/python3.8/dist-packages/wandb/sdk/internal/sender.py", line 238, in send
    send_handler(record)
  File "/usr/local/lib/python3.8/dist-packages/wandb/sdk/internal/sender.py", line 696, in send_run
    self._init_run(run, config_value_dict)
  File "/usr/local/lib/python3.8/dist-packages/wandb/sdk/internal/sender.py", line 720, in _init_run
    server_run, inserted = self._api.upsert_run(
  File "/usr/local/lib/python3.8/dist-packages/wandb/apis/normalize.py", line 27, in wrapper
    raise CommError(err.response, err)
wandb.errors.CommError: <Response [409]>
